2019-05-04 22:08:22,510 ERROR: Exception on /export_posts [GET] [in c:\users\dell\documents\adopt_me\venv\lib\site-packages\flask\app.py:1761]
Traceback (most recent call last):
  File "c:\users\dell\documents\adopt_me\venv\lib\site-packages\redis\connection.py", line 492, in connect
    sock = self._connect()
  File "c:\users\dell\documents\adopt_me\venv\lib\site-packages\redis\connection.py", line 550, in _connect
    raise err
  File "c:\users\dell\documents\adopt_me\venv\lib\site-packages\redis\connection.py", line 538, in _connect
    sock.connect(socket_address)
ConnectionRefusedError: [WinError 10061] Nie mo¿na nawi¹zaæ po³¹czenia, poniewa¿ komputer docelowy aktywnie go odmawia

During handling of the above exception, another exception occurred:

Traceback (most recent call last):
  File "c:\users\dell\documents\adopt_me\venv\lib\site-packages\flask\app.py", line 2292, in wsgi_app
    response = self.full_dispatch_request()
  File "c:\users\dell\documents\adopt_me\venv\lib\site-packages\flask\app.py", line 1815, in full_dispatch_request
    rv = self.handle_user_exception(e)
  File "c:\users\dell\documents\adopt_me\venv\lib\site-packages\flask\app.py", line 1718, in handle_user_exception
    reraise(exc_type, exc_value, tb)
  File "c:\users\dell\documents\adopt_me\venv\lib\site-packages\flask\_compat.py", line 35, in reraise
    raise value
  File "c:\users\dell\documents\adopt_me\venv\lib\site-packages\flask\app.py", line 1813, in full_dispatch_request
    rv = self.dispatch_request()
  File "c:\users\dell\documents\adopt_me\venv\lib\site-packages\flask\app.py", line 1799, in dispatch_request
    return self.view_functions[rule.endpoint](**req.view_args)
  File "c:\users\dell\documents\adopt_me\venv\lib\site-packages\flask_login\utils.py", line 261, in decorated_view
    return func(*args, **kwargs)
  File "C:\Users\Dell\Documents\Adopt_me\app\main\routes.py", line 213, in export_posts
    current_user.launch_task('export_posts', _('Exporting posts...'))
  File "C:\Users\Dell\Documents\Adopt_me\app\models.py", line 153, in launch_task
    *args, **kwargs)
  File "c:\users\dell\documents\adopt_me\venv\lib\site-packages\rq\queue.py", line 327, in enqueue
    at_front=at_front, meta=meta
  File "c:\users\dell\documents\adopt_me\venv\lib\site-packages\rq\queue.py", line 277, in enqueue_call
    job = self.enqueue_job(job, at_front=at_front)
  File "c:\users\dell\documents\adopt_me\venv\lib\site-packages\rq\queue.py", line 353, in enqueue_job
    pipe.execute()
  File "c:\users\dell\documents\adopt_me\venv\lib\site-packages\redis\client.py", line 3514, in execute
    self.shard_hint)
  File "c:\users\dell\documents\adopt_me\venv\lib\site-packages\redis\connection.py", line 994, in get_connection
    connection.connect()
  File "c:\users\dell\documents\adopt_me\venv\lib\site-packages\redis\connection.py", line 497, in connect
    raise ConnectionError(self._error_message(e))
redis.exceptions.ConnectionError: Error 10061 connecting to None:6379. Nie mo¿na nawi¹zaæ po³¹czenia, poniewa¿ komputer docelowy aktywnie go odmawia.
