2019-02-25 19:54:12,908 ERROR: Exception on /follow/natalia [GET] [in c:\users\dell\documents\adopt_me\venv\lib\site-packages\flask\app.py:1761]
Traceback (most recent call last):
  File "c:\users\dell\documents\adopt_me\venv\lib\site-packages\flask\app.py", line 2292, in wsgi_app
    response = self.full_dispatch_request()
  File "c:\users\dell\documents\adopt_me\venv\lib\site-packages\flask\app.py", line 1815, in full_dispatch_request
    rv = self.handle_user_exception(e)
  File "c:\users\dell\documents\adopt_me\venv\lib\site-packages\flask\app.py", line 1718, in handle_user_exception
    reraise(exc_type, exc_value, tb)
  File "c:\users\dell\documents\adopt_me\venv\lib\site-packages\flask\_compat.py", line 35, in reraise
    raise value
  File "c:\users\dell\documents\adopt_me\venv\lib\site-packages\flask\app.py", line 1813, in full_dispatch_request
    rv = self.dispatch_request()
  File "c:\users\dell\documents\adopt_me\venv\lib\site-packages\flask\app.py", line 1799, in dispatch_request
    return self.view_functions[rule.endpoint](**req.view_args)
  File "c:\users\dell\documents\adopt_me\venv\lib\site-packages\flask_login\utils.py", line 261, in decorated_view
    return func(*args, **kwargs)
  File "C:\Users\Dell\Documents\Adopt_me\app\routes.py", line 113, in follow
    return redirect(url_for('user', username=username))
TypeError: redirect() got an unexpected keyword argument 'username'
2019-02-25 19:54:38,719 INFO: Microblog startup [in C:\Users\Dell\Documents\Adopt_me\app\__init__.py:29]
