2019-05-05 19:48:00,895 ERROR: Exception on /api/users/1 [GET] [in c:\users\dell\documents\adopt_me\venv\lib\site-packages\flask\app.py:1761]
Traceback (most recent call last):
  File "c:\users\dell\documents\adopt_me\venv\lib\site-packages\flask\app.py", line 2292, in wsgi_app
    response = self.full_dispatch_request()
  File "c:\users\dell\documents\adopt_me\venv\lib\site-packages\flask\app.py", line 1815, in full_dispatch_request
    rv = self.handle_user_exception(e)
  File "c:\users\dell\documents\adopt_me\venv\lib\site-packages\flask\app.py", line 1718, in handle_user_exception
    reraise(exc_type, exc_value, tb)
  File "c:\users\dell\documents\adopt_me\venv\lib\site-packages\flask\_compat.py", line 35, in reraise
    raise value
  File "c:\users\dell\documents\adopt_me\venv\lib\site-packages\flask\app.py", line 1813, in full_dispatch_request
    rv = self.dispatch_request()
  File "c:\users\dell\documents\adopt_me\venv\lib\site-packages\flask\app.py", line 1799, in dispatch_request
    return self.view_functions[rule.endpoint](**req.view_args)
  File "C:\Users\Dell\Documents\Adopt_me\app\api\users.py", line 8, in get_user
    return jsonify(User.query.get_or_404(id).to_dict())
  File "C:\Users\Dell\Documents\Adopt_me\app\models.py", line 201, in to_dict
    'followers': url_for('api.get_followers', id=self.id),
  File "c:\users\dell\documents\adopt_me\venv\lib\site-packages\flask\helpers.py", line 356, in url_for
    return appctx.app.handle_url_build_error(error, endpoint, values)
  File "c:\users\dell\documents\adopt_me\venv\lib\site-packages\flask\app.py", line 2061, in handle_url_build_error
    reraise(exc_type, exc_value, tb)
  File "c:\users\dell\documents\adopt_me\venv\lib\site-packages\flask\_compat.py", line 35, in reraise
    raise value
  File "c:\users\dell\documents\adopt_me\venv\lib\site-packages\flask\helpers.py", line 345, in url_for
    force_external=external)
  File "c:\users\dell\documents\adopt_me\venv\lib\site-packages\werkzeug\routing.py", line 1776, in build
    raise BuildError(endpoint, values, method, self)
werkzeug.routing.BuildError: Could not build url for endpoint 'api.get_followers' with values ['id']. Did you mean 'api.get_user' instead?
2019-05-05 19:55:50,422 ERROR: Exception on /api/users/1 [GET] [in c:\users\dell\documents\adopt_me\venv\lib\site-packages\flask\app.py:1761]
Traceback (most recent call last):
  File "c:\users\dell\documents\adopt_me\venv\lib\site-packages\flask\app.py", line 2292, in wsgi_app
    response = self.full_dispatch_request()
  File "c:\users\dell\documents\adopt_me\venv\lib\site-packages\flask\app.py", line 1815, in full_dispatch_request
    rv = self.handle_user_exception(e)
  File "c:\users\dell\documents\adopt_me\venv\lib\site-packages\flask\app.py", line 1718, in handle_user_exception
    reraise(exc_type, exc_value, tb)
  File "c:\users\dell\documents\adopt_me\venv\lib\site-packages\flask\_compat.py", line 35, in reraise
    raise value
  File "c:\users\dell\documents\adopt_me\venv\lib\site-packages\flask\app.py", line 1813, in full_dispatch_request
    rv = self.dispatch_request()
  File "c:\users\dell\documents\adopt_me\venv\lib\site-packages\flask\app.py", line 1799, in dispatch_request
    return self.view_functions[rule.endpoint](**req.view_args)
  File "C:\Users\Dell\Documents\Adopt_me\app\api\users.py", line 8, in get_user
    return jsonify(User.query.get_or_404(id).to_dict())
  File "C:\Users\Dell\Documents\Adopt_me\app\models.py", line 201, in to_dict
    'followers': url_for('api.get_followers', id=self.id),
  File "c:\users\dell\documents\adopt_me\venv\lib\site-packages\flask\helpers.py", line 356, in url_for
    return appctx.app.handle_url_build_error(error, endpoint, values)
  File "c:\users\dell\documents\adopt_me\venv\lib\site-packages\flask\app.py", line 2061, in handle_url_build_error
    reraise(exc_type, exc_value, tb)
  File "c:\users\dell\documents\adopt_me\venv\lib\site-packages\flask\_compat.py", line 35, in reraise
    raise value
  File "c:\users\dell\documents\adopt_me\venv\lib\site-packages\flask\helpers.py", line 345, in url_for
    force_external=external)
  File "c:\users\dell\documents\adopt_me\venv\lib\site-packages\werkzeug\routing.py", line 1776, in build
    raise BuildError(endpoint, values, method, self)
werkzeug.routing.BuildError: Could not build url for endpoint 'api.get_followers' with values ['id']. Did you mean 'api.get_user' instead?
2019-05-05 19:55:54,314 ERROR: Exception on /api/users/1 [GET] [in c:\users\dell\documents\adopt_me\venv\lib\site-packages\flask\app.py:1761]
Traceback (most recent call last):
  File "c:\users\dell\documents\adopt_me\venv\lib\site-packages\flask\app.py", line 2292, in wsgi_app
    response = self.full_dispatch_request()
  File "c:\users\dell\documents\adopt_me\venv\lib\site-packages\flask\app.py", line 1815, in full_dispatch_request
    rv = self.handle_user_exception(e)
  File "c:\users\dell\documents\adopt_me\venv\lib\site-packages\flask\app.py", line 1718, in handle_user_exception
    reraise(exc_type, exc_value, tb)
  File "c:\users\dell\documents\adopt_me\venv\lib\site-packages\flask\_compat.py", line 35, in reraise
    raise value
  File "c:\users\dell\documents\adopt_me\venv\lib\site-packages\flask\app.py", line 1813, in full_dispatch_request
    rv = self.dispatch_request()
  File "c:\users\dell\documents\adopt_me\venv\lib\site-packages\flask\app.py", line 1799, in dispatch_request
    return self.view_functions[rule.endpoint](**req.view_args)
  File "C:\Users\Dell\Documents\Adopt_me\app\api\users.py", line 8, in get_user
    return jsonify(User.query.get_or_404(id).to_dict())
  File "C:\Users\Dell\Documents\Adopt_me\app\models.py", line 201, in to_dict
    'followers': url_for('api.get_followers', id=self.id),
  File "c:\users\dell\documents\adopt_me\venv\lib\site-packages\flask\helpers.py", line 356, in url_for
    return appctx.app.handle_url_build_error(error, endpoint, values)
  File "c:\users\dell\documents\adopt_me\venv\lib\site-packages\flask\app.py", line 2061, in handle_url_build_error
    reraise(exc_type, exc_value, tb)
  File "c:\users\dell\documents\adopt_me\venv\lib\site-packages\flask\_compat.py", line 35, in reraise
    raise value
  File "c:\users\dell\documents\adopt_me\venv\lib\site-packages\flask\helpers.py", line 345, in url_for
    force_external=external)
  File "c:\users\dell\documents\adopt_me\venv\lib\site-packages\werkzeug\routing.py", line 1776, in build
    raise BuildError(endpoint, values, method, self)
werkzeug.routing.BuildError: Could not build url for endpoint 'api.get_followers' with values ['id']. Did you mean 'api.get_user' instead?
2019-05-05 19:56:18,654 ERROR: Exception on /api/users/1 [GET] [in c:\users\dell\documents\adopt_me\venv\lib\site-packages\flask\app.py:1761]
Traceback (most recent call last):
  File "c:\users\dell\documents\adopt_me\venv\lib\site-packages\flask\app.py", line 2292, in wsgi_app
    response = self.full_dispatch_request()
  File "c:\users\dell\documents\adopt_me\venv\lib\site-packages\flask\app.py", line 1815, in full_dispatch_request
    rv = self.handle_user_exception(e)
  File "c:\users\dell\documents\adopt_me\venv\lib\site-packages\flask\app.py", line 1718, in handle_user_exception
    reraise(exc_type, exc_value, tb)
  File "c:\users\dell\documents\adopt_me\venv\lib\site-packages\flask\_compat.py", line 35, in reraise
    raise value
  File "c:\users\dell\documents\adopt_me\venv\lib\site-packages\flask\app.py", line 1813, in full_dispatch_request
    rv = self.dispatch_request()
  File "c:\users\dell\documents\adopt_me\venv\lib\site-packages\flask\app.py", line 1799, in dispatch_request
    return self.view_functions[rule.endpoint](**req.view_args)
  File "C:\Users\Dell\Documents\Adopt_me\app\api\users.py", line 8, in get_user
    return jsonify(User.query.get_or_404(id).to_dict())
  File "C:\Users\Dell\Documents\Adopt_me\app\models.py", line 201, in to_dict
    'followers': url_for('api.get_followers', id=self.id),
  File "c:\users\dell\documents\adopt_me\venv\lib\site-packages\flask\helpers.py", line 356, in url_for
    return appctx.app.handle_url_build_error(error, endpoint, values)
  File "c:\users\dell\documents\adopt_me\venv\lib\site-packages\flask\app.py", line 2061, in handle_url_build_error
    reraise(exc_type, exc_value, tb)
  File "c:\users\dell\documents\adopt_me\venv\lib\site-packages\flask\_compat.py", line 35, in reraise
    raise value
  File "c:\users\dell\documents\adopt_me\venv\lib\site-packages\flask\helpers.py", line 345, in url_for
    force_external=external)
  File "c:\users\dell\documents\adopt_me\venv\lib\site-packages\werkzeug\routing.py", line 1776, in build
    raise BuildError(endpoint, values, method, self)
werkzeug.routing.BuildError: Could not build url for endpoint 'api.get_followers' with values ['id']. Did you mean 'api.get_user' instead?
2019-05-05 20:01:04,614 INFO: Microblog startup [in C:\Users\Dell\Documents\Adopt_me\app\__init__.py:68]
