2019-02-11 08:54:58,545 INFO: Microblog startup [in D:\Projekty\adopt_me\app\__init__.py:29]
2019-02-11 08:55:30,111 ERROR: Exception on /edit_profile [POST] [in d:\projekty\adopt_me\venv\lib\site-packages\flask\app.py:1761]
Traceback (most recent call last):
  File "d:\projekty\adopt_me\venv\lib\site-packages\sqlalchemy\engine\base.py", line 1236, in _execute_context
    cursor, statement, parameters, context
  File "d:\projekty\adopt_me\venv\lib\site-packages\sqlalchemy\engine\default.py", line 536, in do_execute
    cursor.execute(statement, parameters)
psycopg2.IntegrityError: B£¥D:  podwójna wartoœæ klucza narusza ograniczenie unikalnoœci "ix_users_username"
DETAIL:  Klucz (username)=(asd) ju¿ istnieje.


The above exception was the direct cause of the following exception:

Traceback (most recent call last):
  File "d:\projekty\adopt_me\venv\lib\site-packages\flask\app.py", line 2292, in wsgi_app
    response = self.full_dispatch_request()
  File "d:\projekty\adopt_me\venv\lib\site-packages\flask\app.py", line 1815, in full_dispatch_request
    rv = self.handle_user_exception(e)
  File "d:\projekty\adopt_me\venv\lib\site-packages\flask\app.py", line 1718, in handle_user_exception
    reraise(exc_type, exc_value, tb)
  File "d:\projekty\adopt_me\venv\lib\site-packages\flask\_compat.py", line 35, in reraise
    raise value
  File "d:\projekty\adopt_me\venv\lib\site-packages\flask\app.py", line 1813, in full_dispatch_request
    rv = self.dispatch_request()
  File "d:\projekty\adopt_me\venv\lib\site-packages\flask\app.py", line 1799, in dispatch_request
    return self.view_functions[rule.endpoint](**req.view_args)
  File "d:\projekty\adopt_me\venv\lib\site-packages\flask_login\utils.py", line 261, in decorated_view
    return func(*args, **kwargs)
  File "D:\Projekty\adopt_me\app\routes.py", line 91, in edit_profile
    db.session.commit()
  File "d:\projekty\adopt_me\venv\lib\site-packages\sqlalchemy\orm\scoping.py", line 162, in do
    return getattr(self.registry(), name)(*args, **kwargs)
  File "d:\projekty\adopt_me\venv\lib\site-packages\sqlalchemy\orm\session.py", line 1023, in commit
    self.transaction.commit()
  File "d:\projekty\adopt_me\venv\lib\site-packages\sqlalchemy\orm\session.py", line 487, in commit
    self._prepare_impl()
  File "d:\projekty\adopt_me\venv\lib\site-packages\sqlalchemy\orm\session.py", line 466, in _prepare_impl
    self.session.flush()
  File "d:\projekty\adopt_me\venv\lib\site-packages\sqlalchemy\orm\session.py", line 2436, in flush
    self._flush(objects)
  File "d:\projekty\adopt_me\venv\lib\site-packages\sqlalchemy\orm\session.py", line 2574, in _flush
    transaction.rollback(_capture_exception=True)
  File "d:\projekty\adopt_me\venv\lib\site-packages\sqlalchemy\util\langhelpers.py", line 67, in __exit__
    compat.reraise(exc_type, exc_value, exc_tb)
  File "d:\projekty\adopt_me\venv\lib\site-packages\sqlalchemy\util\compat.py", line 277, in reraise
    raise value
  File "d:\projekty\adopt_me\venv\lib\site-packages\sqlalchemy\orm\session.py", line 2534, in _flush
    flush_context.execute()
  File "d:\projekty\adopt_me\venv\lib\site-packages\sqlalchemy\orm\unitofwork.py", line 416, in execute
    rec.execute(self)
  File "d:\projekty\adopt_me\venv\lib\site-packages\sqlalchemy\orm\unitofwork.py", line 583, in execute
    uow,
  File "d:\projekty\adopt_me\venv\lib\site-packages\sqlalchemy\orm\persistence.py", line 236, in save_obj
    update,
  File "d:\projekty\adopt_me\venv\lib\site-packages\sqlalchemy\orm\persistence.py", line 976, in _emit_update_statements
    statement, multiparams
  File "d:\projekty\adopt_me\venv\lib\site-packages\sqlalchemy\engine\base.py", line 980, in execute
    return meth(self, multiparams, params)
  File "d:\projekty\adopt_me\venv\lib\site-packages\sqlalchemy\sql\elements.py", line 273, in _execute_on_connection
    return connection._execute_clauseelement(self, multiparams, params)
  File "d:\projekty\adopt_me\venv\lib\site-packages\sqlalchemy\engine\base.py", line 1099, in _execute_clauseelement
    distilled_params,
  File "d:\projekty\adopt_me\venv\lib\site-packages\sqlalchemy\engine\base.py", line 1240, in _execute_context
    e, statement, parameters, cursor, context
  File "d:\projekty\adopt_me\venv\lib\site-packages\sqlalchemy\engine\base.py", line 1458, in _handle_dbapi_exception
    util.raise_from_cause(sqlalchemy_exception, exc_info)
  File "d:\projekty\adopt_me\venv\lib\site-packages\sqlalchemy\util\compat.py", line 296, in raise_from_cause
    reraise(type(exception), exception, tb=exc_tb, cause=cause)
  File "d:\projekty\adopt_me\venv\lib\site-packages\sqlalchemy\util\compat.py", line 276, in reraise
    raise value.with_traceback(tb)
  File "d:\projekty\adopt_me\venv\lib\site-packages\sqlalchemy\engine\base.py", line 1236, in _execute_context
    cursor, statement, parameters, context
  File "d:\projekty\adopt_me\venv\lib\site-packages\sqlalchemy\engine\default.py", line 536, in do_execute
    cursor.execute(statement, parameters)
sqlalchemy.exc.IntegrityError: (psycopg2.IntegrityError) B£¥D:  podwójna wartoœæ klucza narusza ograniczenie unikalnoœci "ix_users_username"
DETAIL:  Klucz (username)=(asd) ju¿ istnieje.
 [SQL: 'UPDATE users SET username=%(username)s, about_me=%(about_me)s WHERE users.id = %(users_id)s'] [parameters: {'username': 'asd', 'about_me': 'Parê s³ów o mnie. ', 'users_id': 2}] (Background on this error at: http://sqlalche.me/e/gkpj)
